<?xml version="1.0" ?>
<!-- =================================================================================== -->
<!-- |    This document was autogenerated by xacro from pendulum.urdf.xacro            | -->
<!-- |    EDITING THIS FILE BY HAND IS NOT RECOMMENDED                                 | -->
<!-- =================================================================================== -->
<robot name="pendulum_cart">
  <!-- #region MATERIAL-->
  <material name="blue">
    <color rgba="0 0 0.8 1"/>
  </material>
  <material name="white">
    <color rgba="1 1 1 1"/>
  </material>
  <!-- #endregion -->
  <!-- #region XACRO_MACROS -->
  <!-- #region constants -->
  <!-- <xacro:include filename="$(find double_inverted_pendulum)/description/materials.xacro" /> -->
  <!-- #endregion -->
  <!-- #endregion -->
  <!-- #endregion -->
  <!-- #endregion -->
  <!-- ROBOT BEGINS HERE -->
  <!-- ROBOT BEGINS HERE -->
  <!-- ROBOT BEGINS HERE -->
  <!-- #region BASE -->
  <link name="base_link">
    <visual>
      <origin rpy="0 0 0" xyz="0 0 0"/>
      <geometry>
        <box size="0.5 0.5 0.1"/>
      </geometry>
      <material name="blue"/>
    </visual>
    <collision>
      <origin rpy="0 0 0" xyz="0 0 0"/>
      <geometry>
        <box size="0.5 0.5 0.1"/>
      </geometry>
    </collision>
    <inertial>
      <mass value="1000"/>
      <inertia ixx="21.666666666666668" ixy="0" ixz="0" iyy="41.666666666666664" iyz="0" izz="21.666666666666668"/>
    </inertial>
  </link>
  <!-- #endregion -->
  <!-- #region FIRST_PENDULUM -->
  <link name="first_pendulum">
    <visual>
      <origin rpy="0 0 0" xyz="0 0 1.0"/>
      <geometry>
        <cylinder length="2.0" radius="0.02"/>
      </geometry>
      <material name="white"/>
    </visual>
    <collision>
      <origin rpy="0 0 0" xyz="0 0 1.0"/>
      <geometry>
        <cylinder length="1.6" radius="2.0"/>
      </geometry>
    </collision>
    <inertial>
      <mass value="1"/>
      <inertia ixx="0.3334333333333333" ixy="0" ixz="0" iyy="0.3334333333333333" iyz="0" izz="0.0002"/>
    </inertial>
  </link>
  <link name="first_pendulum_roll">
    <inertial>
      <mass value="0.01"/>
      <inertia ixx="0.01" ixy="0" ixz="0" iyy="0.01" iyz="0" izz="0.01"/>
    </inertial>
  </link>
  <link name="first_pendulum_pitch">
    <inertial>
      <mass value="0.01"/>
      <inertia ixx="0.01" ixy="0" ixz="0" iyy="0.01" iyz="0" izz="0.01"/>
    </inertial>
  </link>
  <joint name="base_to_first_pendulum_roll" type="revolute">
    <parent link="base_link"/>
    <child link="first_pendulum_roll"/>
    <!-- joint of child is xyz away from parent -->
    <origin xyz="0 0 0.05"/>
    <axis xyz="1 0 0"/>
    <limit effort="1" lower="-1.57" upper="1.57" velocity="100"/>
    <dynamics damping="1" friction="1"/>
  </joint>
  <joint name="base_to_first_pendulum_pitch" type="revolute">
    <parent link="first_pendulum_roll"/>
    <child link="first_pendulum_pitch"/>
    <!-- joint of child is xyz away from parent -->
    <origin xyz="0 0 0"/>
    <axis xyz="0 1 0"/>
    <limit effort="1" lower="0" upper="0" velocity="100"/>
    <dynamics damping="1" friction="1"/>
  </joint>
  <joint name="base_to_first_pendulum" type="fixed">
    <parent link="first_pendulum_pitch"/>
    <child link="first_pendulum"/>
    <!-- joint of child is xyz away from parent -->
    <origin xyz="0 0 0"/>
  </joint>
  <!-- #endregion -->
  <!-- #region SECOND_PENDULUM -->
  <link name="second_pendulum">
    <visual>
      <origin rpy="0 0 0" xyz="0 0 1.0"/>
      <geometry>
        <cylinder length="2.0" radius="0.02"/>
      </geometry>
      <material name="blue"/>
    </visual>
    <collision>
      <origin rpy="0 0 0" xyz="0 0 1.0"/>
      <geometry>
        <cylinder length="1.6" radius="2.0"/>
      </geometry>
    </collision>
    <inertial>
      <mass value="1"/>
      <inertia ixx="0.3334333333333333" ixy="0" ixz="0" iyy="0.3334333333333333" iyz="0" izz="0.0002"/>
    </inertial>
  </link>
  <link name="second_pendulum_roll">
    <inertial>
      <mass value="0.01"/>
      <inertia ixx="0.01" ixy="0" ixz="0" iyy="0.01" iyz="0" izz="0.01"/>
    </inertial>
  </link>
  <link name="second_pendulum_pitch">
    <inertial>
      <mass value="0.01"/>
      <inertia ixx="0.01" ixy="0" ixz="0" iyy="0.01" iyz="0" izz="0.01"/>
    </inertial>
  </link>
  <joint name="base_to_second_pendulum_roll" type="revolute">
    <parent link="first_pendulum"/>
    <child link="second_pendulum_roll"/>
    <!-- joint of child is xyz away from parent -->
    <origin xyz="0 0 2.0"/>
    <axis xyz="1 0 0"/>
    <limit effort="1" lower="-1.57" upper="1.57" velocity="1"/>
    <dynamics damping="1" friction="1"/>
  </joint>
  <joint name="base_to_second_pendulum_pitch" type="revolute">
    <parent link="second_pendulum_roll"/>
    <child link="second_pendulum_pitch"/>
    <!-- joint of child is xyz away from parent -->
    <origin xyz="0 0 0"/>
    <axis xyz="0 1 0"/>
    <limit effort="1" lower="0" upper="0" velocity="1"/>
    <dynamics damping="1" friction="1"/>
  </joint>
  <joint name="base_to_second_pendulum" type="fixed">
    <parent link="second_pendulum_pitch"/>
    <child link="second_pendulum"/>
    <!-- joint of child is xyz away from parent -->
    <origin xyz="0 0 0"/>
  </joint>
  <!-- #endregion -->
  <!-- #region WHEELS -->
  <!-- #region FRONT_LEFT_WHEEL -->
  <link name="front_left_wheel">
    <visual>
      <origin rpy="0 1.570796327 0" xyz="0.051 0 0"/>
      <geometry>
        <cylinder length="0.1" radius="0.1"/>
      </geometry>
      <material name="white"/>
    </visual>
    <collision>
      <origin rpy="0 1.570796327 0" xyz="0.051 0 0"/>
      <geometry>
        <cylinder length="0.1" radius="0.1"/>
      </geometry>
    </collision>
    <inertial>
      <mass value="0.3"/>
      <inertia ixx="0.001" ixy="0" ixz="0" iyy="0.001" iyz="0" izz="0.0015"/>
    </inertial>
  </link>
  <joint name="base_to_front_left_wheel" type="continuous">
    <parent link="base_link"/>
    <child link="front_left_wheel"/>
    <!-- joint of child is xyz away from parent -->
    <origin xyz="0.25 0.25 -0.05"/>
    <axis xyz="1 0 0"/>
  </joint>
  <!-- #endregion -->
  <!-- #region FRONT_RIGHT_WHEEL -->
  <link name="front_right_wheel">
    <visual>
      <origin rpy="0 -1.570796327 0" xyz="0.051 0 0"/>
      <geometry>
        <cylinder length="0.1" radius="0.1"/>
      </geometry>
      <material name="white"/>
    </visual>
    <collision>
      <origin rpy="0 -1.570796327 0" xyz="0.051 0 0"/>
      <geometry>
        <cylinder length="0.1" radius="0.1"/>
      </geometry>
    </collision>
    <inertial>
      <mass value="0.3"/>
      <inertia ixx="0.001" ixy="0" ixz="0" iyy="0.001" iyz="0" izz="0.0015"/>
    </inertial>
  </link>
  <joint name="base_to_front_right_wheel" type="continuous">
    <parent link="base_link"/>
    <child link="front_right_wheel"/>
    <!-- joint of child is xyz away from parent -->
    <origin xyz="0.25 -0.25 -0.05"/>
    <axis xyz="1 0 0"/>
  </joint>
  <!-- #endregion -->
  <!-- #region BACK_LEFT_WHEEL -->
  <link name="back_left_wheel">
    <visual>
      <origin rpy="0 1.570796327 0" xyz="-0.051 0 0"/>
      <geometry>
        <cylinder length="0.1" radius="0.1"/>
      </geometry>
      <material name="white"/>
    </visual>
    <collision>
      <origin rpy="0 1.570796327 0" xyz="-0.051 0 0"/>
      <geometry>
        <cylinder length="0.1" radius="0.1"/>
      </geometry>
    </collision>
    <inertial>
      <mass value="0.3"/>
      <inertia ixx="0.001" ixy="0" ixz="0" iyy="0.001" iyz="0" izz="0.0015"/>
    </inertial>
  </link>
  <joint name="base_to_back_left_wheel" type="continuous">
    <parent link="base_link"/>
    <child link="back_left_wheel"/>
    <!-- joint of child is xyz away from parent -->
    <origin xyz="-0.25 0.25 -0.05"/>
    <axis xyz="1 0 0"/>
  </joint>
  <!-- #endregion -->
  <!-- #region BACK_RIGHT_WHEEL -->
  <link name="back_right_wheel">
    <visual>
      <origin rpy="0 1.570796327 0" xyz="-0.051 0 0"/>
      <geometry>
        <cylinder length="0.1" radius="0.1"/>
      </geometry>
      <material name="white"/>
    </visual>
    <collision>
      <origin rpy="0 1.570796327 0" xyz="-0.051 0 0"/>
      <geometry>
        <cylinder length="0.1" radius="0.1"/>
      </geometry>
    </collision>
    <inertial>
      <mass value="0.3"/>
      <inertia ixx="0.001" ixy="0" ixz="0" iyy="0.001" iyz="0" izz="0.0015"/>
    </inertial>
  </link>
  <joint name="base_to_back_right_wheel" type="continuous">
    <parent link="base_link"/>
    <child link="back_right_wheel"/>
    <!-- joint of child is xyz away from parent -->
    <origin xyz="-0.25 -0.25 -0.05"/>
    <axis xyz="1 0 0"/>
  </joint>
  <!-- #endregion -->
  <!-- #endregion -->
</robot>
