<?xml version="1.0" ?>
<!-- =================================================================================== -->
<!-- |    This document was autogenerated by xacro from pendulum2.urdf.xacro           | -->
<!-- |    EDITING THIS FILE BY HAND IS NOT RECOMMENDED                                 | -->
<!-- =================================================================================== -->
<robot name="pendulum_cart">
  <material name="black">
    <color rgba="0.0 0.0 0.0 1.0"/>
  </material>
  <material name="blue">
    <color rgba="0.0 0.0 0.8 1.0"/>
  </material>
  <material name="green">
    <color rgba="0.0 0.8 0.0 1.0"/>
  </material>
  <material name="grey">
    <color rgba="0.2 0.2 0.2 1.0"/>
  </material>
  <material name="orange">
    <color rgba="1.0 0.4235294117647059 0.0392156862745098 1.0"/>
  </material>
  <material name="brown">
    <color rgba="0.8705882352941177 0.8117647058823529 0.7647058823529411 1.0"/>
  </material>
  <material name="red">
    <color rgba="0.8 0.0 0.0 1.0"/>
  </material>
  <material name="white">
    <color rgba="1.0 1.0 1.0 1.0"/>
  </material>
  <gazebo reference="base_link">
    <selfCollide>true</selfCollide>
    <material>Gazebo/Orange</material>
  </gazebo>
  <gazebo reference="first_pendulum">
    <selfCollide>true</selfCollide>
  </gazebo>
  <gazebo reference="second_pendulum">
    <selfCollide>true</selfCollide>
  </gazebo>
  <!-- #region MATERIAL-->
  <!-- <material name="blue">
        <color rgba="0 0 0.8 1"/>
    </material>

    <material name="white">
        <color rgba="1 1 1 1"/>
    </material> -->
  <!-- #endregion -->
  <!-- #region XACRO_MACROS -->
  <!-- #endregion -->
  <!-- #endregion -->
  <!-- #endregion -->
  <!-- #endregion -->
  <!-- ROBOT BEGINS HERE -->
  <!-- ROBOT BEGINS HERE -->
  <!-- ROBOT BEGINS HERE -->
  <!-- #region BASE -->
  <link name="base_link">
    <visual>
      <origin rpy="0 0 0" xyz="0 0 0"/>
      <geometry>
        <box size="0.5 0.5 0.1"/>
      </geometry>
      <!-- <material name="${material}"/> -->
    </visual>
    <collision>
      <origin rpy="0 0 0" xyz="0 0 0"/>
      <geometry>
        <box size="0.5 0.5 0.1"/>
      </geometry>
    </collision>
    <inertial>
      <mass value="1000"/>
      <inertia ixx="21.666666666666668" ixy="0" ixz="0" iyy="41.666666666666664" iyz="0" izz="21.666666666666668"/>
    </inertial>
  </link>
  <!-- #endregion -->
  <!-- #region PENDULUM_JOINT -->
  <link name="pendulum_joint">
    <visual>
      <origin rpy="0 0 0" xyz="0 0 -0.025"/>
      <geometry>
        <box size="0.05 0.05 0.1"/>
      </geometry>
      <!-- <material name="${material}"/> -->
    </visual>
    <collision>
      <origin rpy="0 0 0" xyz="0 0 -0.025"/>
      <geometry>
        <box size="0.05 0.05 0.1"/>
      </geometry>
    </collision>
    <inertial>
      <mass value="10"/>
      <inertia ixx="0.010416666666666668" ixy="0" ixz="0" iyy="0.0041666666666666675" iyz="0" izz="0.010416666666666668"/>
    </inertial>
  </link>
  <joint name="base_to_pendulum_joint" type="fixed">
    <parent link="base_link"/>
    <child link="pendulum_joint"/>
    <!-- joint of child is xyz away from parent -->
    <origin xyz="0 0 0.125"/>
  </joint>
  <!-- #endregion -->
  <!-- #region FIRST_PENDULUM -->
  <link name="first_pendulum">
    <visual>
      <origin rpy="0 0 0" xyz="0 0 0.225"/>
      <geometry>
        <box size="0.05 0.05 0.5"/>
      </geometry>
      <!-- <material name="${material}"/> -->
    </visual>
    <collision>
      <origin rpy="0 0 0" xyz="0 0 0.225"/>
      <geometry>
        <box size="0.05 0.05 0.5"/>
      </geometry>
    </collision>
    <inertial>
      <mass value="2"/>
      <inertia ixx="0.042083333333333334" ixy="0" ixz="0" iyy="0.0008333333333333335" iyz="0" izz="0.042083333333333334"/>
    </inertial>
  </link>
  <joint name="pendulum_joint_to_first_pendulum" type="continuous">
    <parent link="pendulum_joint"/>
    <child link="first_pendulum"/>
    <!-- joint of child is xyz away from parent -->
    <origin xyz="0.053000000000000005 0 0"/>
    <axis xyz="1 0 0"/>
    <dynamics damping="0.0" friction="0.1"/>
  </joint>
  <!-- #endregion -->
  <!-- #region SECOND_PENDULUM -->
  <link name="second_pendulum">
    <visual>
      <origin rpy="0 0 0" xyz="0 0 0.225"/>
      <geometry>
        <box size="0.05 0.05 0.5"/>
      </geometry>
      <!-- <material name="${material}"/> -->
    </visual>
    <collision>
      <origin rpy="0 0 0" xyz="0 0 0.225"/>
      <geometry>
        <box size="0.05 0.05 0.5"/>
      </geometry>
    </collision>
    <inertial>
      <mass value="2"/>
      <inertia ixx="0.042083333333333334" ixy="0" ixz="0" iyy="0.0008333333333333335" iyz="0" izz="0.042083333333333334"/>
    </inertial>
  </link>
  <joint name="first_pendulum_to_second_pendulum" type="continuous">
    <parent link="first_pendulum"/>
    <child link="second_pendulum"/>
    <!-- joint of child is xyz away from parent -->
    <origin xyz="-0.053000000000000005 0 0.45"/>
    <axis xyz="1 0 0"/>
    <dynamics damping="0.0" friction="0.1"/>
  </joint>
  <!-- #endregion -->
  <!-- #region WHEELS -->
  <!-- #region FRONT_LEFT_WHEEL -->
  <link name="front_left_wheel">
    <visual>
      <origin rpy="0 1.570796327 0" xyz="0.051 0 0"/>
      <geometry>
        <cylinder length="0.1" radius="0.1"/>
      </geometry>
      <!-- <material name="${material}"/> -->
    </visual>
    <collision>
      <origin rpy="0 1.570796327 0" xyz="0.051 0 0"/>
      <geometry>
        <cylinder length="0.1" radius="0.1"/>
      </geometry>
    </collision>
    <inertial>
      <mass value="0.3"/>
      <inertia ixx="0.001" ixy="0" ixz="0" iyy="0.001" iyz="0" izz="0.0015"/>
    </inertial>
  </link>
  <joint name="base_to_front_left_wheel" type="continuous">
    <parent link="base_link"/>
    <child link="front_left_wheel"/>
    <!-- joint of child is xyz away from parent -->
    <origin xyz="0.25 0.25 -0.05"/>
    <axis xyz="1 0 0"/>
  </joint>
  <!-- #endregion -->
  <!-- #region FRONT_RIGHT_WHEEL -->
  <link name="front_right_wheel">
    <visual>
      <origin rpy="0 -1.570796327 0" xyz="0.051 0 0"/>
      <geometry>
        <cylinder length="0.1" radius="0.1"/>
      </geometry>
      <!-- <material name="${material}"/> -->
    </visual>
    <collision>
      <origin rpy="0 -1.570796327 0" xyz="0.051 0 0"/>
      <geometry>
        <cylinder length="0.1" radius="0.1"/>
      </geometry>
    </collision>
    <inertial>
      <mass value="0.3"/>
      <inertia ixx="0.001" ixy="0" ixz="0" iyy="0.001" iyz="0" izz="0.0015"/>
    </inertial>
  </link>
  <joint name="base_to_front_right_wheel" type="continuous">
    <parent link="base_link"/>
    <child link="front_right_wheel"/>
    <!-- joint of child is xyz away from parent -->
    <origin xyz="0.25 -0.25 -0.05"/>
    <axis xyz="1 0 0"/>
  </joint>
  <!-- #endregion -->
  <!-- #region BACK_LEFT_WHEEL -->
  <link name="back_left_wheel">
    <visual>
      <origin rpy="0 1.570796327 0" xyz="-0.051 0 0"/>
      <geometry>
        <cylinder length="0.1" radius="0.1"/>
      </geometry>
      <!-- <material name="${material}"/> -->
    </visual>
    <collision>
      <origin rpy="0 1.570796327 0" xyz="-0.051 0 0"/>
      <geometry>
        <cylinder length="0.1" radius="0.1"/>
      </geometry>
    </collision>
    <inertial>
      <mass value="0.3"/>
      <inertia ixx="0.001" ixy="0" ixz="0" iyy="0.001" iyz="0" izz="0.0015"/>
    </inertial>
  </link>
  <joint name="base_to_back_left_wheel" type="continuous">
    <parent link="base_link"/>
    <child link="back_left_wheel"/>
    <!-- joint of child is xyz away from parent -->
    <origin xyz="-0.25 0.25 -0.05"/>
    <axis xyz="1 0 0"/>
  </joint>
  <!-- #endregion -->
  <!-- #region BACK_RIGHT_WHEEL -->
  <link name="back_right_wheel">
    <visual>
      <origin rpy="0 1.570796327 0" xyz="-0.051 0 0"/>
      <geometry>
        <cylinder length="0.1" radius="0.1"/>
      </geometry>
      <!-- <material name="${material}"/> -->
    </visual>
    <collision>
      <origin rpy="0 1.570796327 0" xyz="-0.051 0 0"/>
      <geometry>
        <cylinder length="0.1" radius="0.1"/>
      </geometry>
    </collision>
    <inertial>
      <mass value="0.3"/>
      <inertia ixx="0.001" ixy="0" ixz="0" iyy="0.001" iyz="0" izz="0.0015"/>
    </inertial>
  </link>
  <joint name="base_to_back_right_wheel" type="continuous">
    <parent link="base_link"/>
    <child link="back_right_wheel"/>
    <!-- joint of child is xyz away from parent -->
    <origin xyz="-0.25 -0.25 -0.05"/>
    <axis xyz="1 0 0"/>
  </joint>
  <!-- #endregion -->
  <!-- #endregion -->
</robot>
